Workbook

Sheet IS
B2: Consolidated Statements of Earnings - USD ($) | C2: 12 Months Ended
B3: shares in Millions, $ in Millions | C3: Oct. 01, 2023 | D3: Sep. 29, 2024 | E3: Sep. 28, 2025 | G3: 2026 Projected | H3: 2027 Projected | I3: 2028 Projected | J3: 2029 Projected | K3: 2030 Projected
B4: Net Revenues:
B5: Revenues | C5: 35975.6 | D5: 36176.2 | E5: 37184.4 | G5: =E5*(1+Assumption!G4) -> 39787.308 | H5: =G5*(1+Assumption!G4) -> 42572.42 | I5: =H5*(1+Assumption!G4) -> 45552.489 | J5: =I5*(1+Assumption!G7) -> 49424.45 | K5: =J5*(1+Assumption!G8) -> 52884.162
B6: Product and distribution costs | C6: 11409.1 | D6: 11180.6 | E6: 11658.2 | G6: =G5-G7 -> 12135.129 | H6: =H5-H7 -> 12984.588 | I6: =I5-I7 -> 13893.509 | J6: =J5-J7 -> 15074.457 | K6: =K5-K7 -> 16129.669
B7: Gross Profit | C7: =(C5-C6) -> 24566.5 | D7: =(D5-D6) -> 24995.6 | E7: =(E5-E6) -> 25526.2 | G7: =G5*Assumption!$G$11 -> 27652.179 | H7: =H5*Assumption!$G$11 -> 29587.832 | I7: =I5*Assumption!$G$11 -> 31658.98 | J7: =J5*Assumption!$G$11 -> 34349.993 | K7: =K5*Assumption!$G$11 -> 36754.493
B8: Store operating expenses | C8: 14720.3 | D8: 15286.5 | E8: 17058.9 | G8: =G5*Assumption!$G$14 -> 16710.669 | H8: =H5*Assumption!$G$14 -> 17880.416 | I8: =I5*Assumption!$G$14 -> 19132.045 | J8: =J5*Assumption!$G$14 -> 20758.269 | K8: =K5*Assumption!$G$14 -> 22211.348
B9: Other operating expenses | C9: 539.4 | D9: 565.6 | E9: 584.6 | G9: =G5*Assumption!$G$17 -> 596.80962 | H9: =H5*Assumption!$G$17 -> 638.58629 | I9: =I5*Assumption!$G$17 -> 683.28733 | J9: =J5*Assumption!$G$17 -> 741.36676 | K9: =K5*Assumption!$G$17 -> 793.26243
B10: Depreciation and amortization expenses | C10: 1362.6 | D10: 1512.6 | E10: 1684.7 | G10: =G5*Assumption!$G$16 -> 1710.8542 | H10: =H5*Assumption!$G$16 -> 1830.614 | I10: =I5*Assumption!$G$16 -> 1958.757 | J10: =J5*Assumption!$G$16 -> 2125.2514 | K10: =K5*Assumption!$G$16 -> 2274.019
B11: General and administrative expenses | C11: 2441.3 | D11: 2523.3 | E11: 2617.2 | G11: =G5*Assumption!$G$15 -> 2745.3243 | H11: =H5*Assumption!$G$15 -> 2937.4969 | I11: =I5*Assumption!$G$15 -> 3143.1217 | J11: =J5*Assumption!$G$15 -> 3410.2871 | K11: =K5*Assumption!$G$15 -> 3649.0072
B12: Restructuring and impairments | C12: 21.8 | D12: 0 | E12: 892 | G12: 0 | H12: 0 | I12: 0 | J12: 0 | K12: 0
B13: Total operating expenses | C13: 30494.5 | D13: 31068.6 | E13: 34495.6 | G13: =SUM(G8:G12)+G6 -> 33898.786 | H13: =SUM(H8:H12)+H6 -> 36271.701 | I13: =SUM(I8:I12)+I6 -> 38810.721 | J13: =SUM(J8:J12)+J6 -> 42109.632 | K13: =SUM(K8:K12)+K6 -> 45057.306
B14: Income from equity investees | C14: 298.4 | D14: 301.2 | E14: 247.8 | G14: =247.8 -> 247.8 | H14: 247.8 | I14: 247 | J14: 247.8 | K14: 247.8
B15: Operating income | C15: 5870.8 | D15: 5408.8 | E15: 2936.6 | G15: =SUM(G5-G13)+G14 -> 6136.3216 | H15: =SUM(H5-H13)+H14 -> 6548.5181 | I15: =SUM(I5-I13)+I14 -> 6988.7684 | J15: =SUM(J5-J13)+J14 -> 7562.6187 | K15: =SUM(K5-K13)+K14 -> 8074.656
B16: Interest income and other, net | C16: 81.2 | D16: 122.8 | E16: 113.3 | G16: 113.3 | H16: 113.3 | I16: 113.3 | J16: 113.3 | K16: 113.3
B17: Interest expense | C17: -550.1 | D17: -562 | E17: -542.6 | G17: -550 | H17: -550 | I17: -550 | J17: -550 | K17: -550
B18: Earnings before income taxes | C18: 5401.9 | D18: 4969.6 | E18: 2507.3 | G18: =SUM(G15:G16)-G17 -> 6799.6216 | H18: =SUM(H15:H16)-H17 -> 7211.8181 | I18: =SUM(I15:I16)-I17 -> 7652.0684 | J18: =SUM(J15:J16)-J17 -> 8225.9187 | K18: =SUM(K15:K16)-K17 -> 8737.956
B19: Income tax expense | C19: 1277.2 | D19: 1207.3 | E19: 650.6 | G19: =G18*Assumption!$G$21 -> 1631.9092 | H19: =H18*Assumption!$G$21 -> 1730.8363 | I19: =I18*Assumption!$G$21 -> 1836.4964 | J19: =J18*Assumption!$G$21 -> 1974.2205 | K19: =K18*Assumption!$G$21 -> 2097.1094
B20: Net earnings including noncontrolling interests | C20: 4124.7 | D20: 3762.3 | E20: 1856.7 | G20: =G18-G19 -> 5167.7124 | H20: =H18-H19 -> 5480.9818 | I20: =I18-I19 -> 5815.572 | J20: =J18-J19 -> 6251.6982 | K20: =K18-K19 -> 6640.8465
B21: Net earnings attributable to noncontrolling interest | C21: 0.2 | D21: 1.4 | E21: 0.3 | G21: 0.3 | H21: 0.3 | I21: 0.3 | J21: 0.3 | K21: 0.3
B22: Net earnings attributable to Starbucks | C22: $ 4,124.5 | D22: $ 3,760.9 | E22: $ 1,856.4 | G22: =G20-G21 -> 5167.4124 | H22: =H20-H21 -> 5480.6818 | I22: =I20-I21 -> 5815.272 | J22: =J20-J21 -> 6251.3982 | K22: =K20-K21 -> 6640.5465
B23: Earnings Per Share, Basic | C23: $ 3.60 | D23: $ 3.32 | E23: $ 1.63 | G23: =G22/G26 -> 4.5487785 | H23: =H22/H26 -> 4.8118365 | I23: =I22/I26 -> 5.0921821 | J23: =J22/J26 -> 5.4597364 | K23: =K22/K26 -> 5.7844482
B24: Earnings/(loss) Per Share, Diluted | C24: $ 3.58 | D24: $ 3.31 | E24: $ 1.63 | G24: =G23 -> 4.5487785 | H24: =H23 -> 4.8118365 | I24: =I23 -> 5.0921821 | J24: =J23 -> 5.4597364 | K24: =K23 -> 5.7844482
B25: Weighted average shares outstanding:
B26: Basic | C26: 1146.8 | D26: 1133.8 | E26: 1136 | G26: 1136 | H26: 1139 | I26: 1142 | J26: 1145 | K26: 1148
B27: Diluted | C27: 1151.3 | D27: 1137.3 | E27: 1139.8 | G27: 1139 | H27: 1142 | I27: 1145 | J27: 1148 | K27: 1151
B28: Gain (Loss) on Disposition of Assets | C28: $ 91.3 | D28: $ 0.0 | E28: $ 0.0 | G28: 0 | H28: 0 | I28: 0 | J28: 0 | K28: 0
B29: Company-Operated Stores [Member]

Sheet Balance Sheet
A1: Consolidated Balance Sheets - USD ($) | B1: Sep 29,2023(Historical) | C1: Sep. 29, 2024(Historical) | D1: Sep. 28, 2025 (Historical) | F1: 2026 Projected | G1: 2027(projected) | H1: 2028(Projected) | I1: 2029 Projected | J1: 2030 Projected
A2: $ in Millions
A3: Current assets:
A4: Cash, Cash Equivalent, Restricted Cash, and Restricted Cash Equivalent, Continuing Operation | B4: 3551.5 | C4: $ 3,286.2 | D4: $ 3,219.8 | F4: ='Cash Flow '!G50 -> 5645.9225 | G4: ='Cash Flow '!H50 -> 8440.2455 | H4: ='Cash Flow '!I50 -> 11032.437 | I4: ='Cash Flow '!J50 -> 13762.345 | J4: ='Cash Flow '!K50 -> 16628.622
A5: Short-term Investments | B5: 401.5 | C5: 257 | D5: 247.2 | F5: 247.2 | G5: 247.2 | H5: 247.2 | I5: 247.2 | J5: 247.2
A6: Accounts Receivable, net | B6: 1184.1 | C6: 1213.8 | D6: 1277.5 | F6: =IS!G5*Assumption!$G$28/365 -> 1308.0759 | G6: =IS!H5*Assumption!$G$28/365 -> 1399.6412 | H6: =IS!I5*Assumption!$G$28/365 -> 1497.6161 | I6: =IS!J5*Assumption!$G$28/365 -> 1624.9134 | J6: =IS!K5*Assumption!$G$28/365 -> 1738.6574
A7: Inventory, Net | B7: 1806.4 | C7: 1777.3 | D7: 2185.6 | F7: =IS!G6*Assumption!$G$29/365 -> 2061.3096 | G7: =IS!H6*Assumption!$G$29/365 -> 2205.6012 | H7: =IS!I6*Assumption!$G$29/365 -> 2359.9933 | I7: =IS!J6*Assumption!$G$29/365 -> 2560.5928 | J7: =IS!K6*Assumption!$G$29/365 -> 2739.8343
A8: Prepaid Expense and Other Assets, Current | B8: 359.9 | C8: 313.1 | D8: 452.2 | F8: 452.2 | G8: 452.2 | H8: 452.2 | I8: 452.2 | J8: 452.2
A9: Assets, Current | B9: =SUM(B4:B8) -> 7303.4 | C9: 6847.4 | D9: 7382.3 | F9: =SUM(F4:F8) -> 9714.708 | G9: =SUM(G4:G8) -> 12744.888 | H9: =SUM(H4:H8) -> 15589.447 | I9: =SUM(I4:I8) -> 18647.252 | J9: =SUM(J4:J8) -> 21806.513
A10: Long-term investments | B10: 247.4 | C10: 276 | D10: 246.9 | F10: 246.9 | G10: 246.9 | H10: 246.9 | I10: 246.9 | J10: 246.9
A11: Equity Investments | B11: 439.9 | C11: 463.9 | D11: 466.2 | F11: 466.2 | G11: 466.2 | H11: 466.2 | I11: 466.2 | J11: 466.2
A12: Property, Plant and Equipment, Net | B12: 7387.1 | C12: 8665.5 | D12: 8493.5 | F12: =(D12+IS!G5*Assumption!$G$25-IS!G10) -> 9169.8842 | G12: =(F12+IS!H5*Assumption!$G$25-IS!H10) -> 9893.6154 | H12: =(G12+IS!I5*Assumption!$G$25-IS!I10) -> 10668.008 | I12: =(H12+IS!J5*Assumption!$G$25-IS!J10) -> 11508.223 | J12: =(I12+IS!K5*Assumption!$G$25-IS!K10) -> 12407.254
A13: Operating Lease, Right-of-Use Asset | B13: 8412.6 | C13: 9286.2 | D13: 9315.7 | F13: 9315.7 | G13: 9315.7 | H13: 9315.7 | I13: 9315.7 | J13: 9315.7
A14: Deferred Income Tax Assets, Net | B14: 1769.8 | C14: 1766.7 | D14: 1826.9 | F14: 1826.9 | G14: 1826.9 | H14: 1826.9 | I14: 1826.9 | J14: 1826.9
A15: Other Assets, Noncurrent | B15: 546.5 | C15: 617 | D15: 752.5 | F15: 752.5 | G15: 752.5 | H15: 752.5 | I15: 752.5 | J15: 752.5
A16: Intangible Assets, Net (Excluding Goodwill) | B16: 120.5 | C16: 100.9 | D16: 166.8 | F16: 166.8 | G16: 166.8 | H16: 166.8 | I16: 166.8 | J16: 166.8
A17: Goodwill | B17: 3218.3 | C17: 3315.7 | D17: 3368.9 | F17: 3368.9 | G17: 3368.9 | H17: 3368.9 | I17: 3368.9 | J17: 3368.9
A18: Assets | B18: =SUM(B4:B17)-(B9) -> 29445.5 | C18: 31339.3 | D18: 32019.7 | F18: =SUM(F9:F17) -> 35028.492 | G18: =SUM(G9:G17) -> 38782.403 | H18: =SUM(H9:H17) -> 42401.354 | I18: =SUM(I9:I17) -> 46299.375 | J18: =SUM(J9:J17) -> 50357.668
A19: Current liabilities:
A20: Accounts Payable, Current | B20: 1544.3 | C20: 1595.5 | D20: 1852.8 | F20: =IS!G6*Assumption!$G$30/365 -> 1828.5811 | G20: =IS!H6*Assumption!$G$30/365 -> 1956.5817 | H20: =IS!I6*Assumption!$G$30/365 -> 2093.5425 | I20: =IS!J6*Assumption!$G$30/365 -> 2271.4936 | J20: =IS!K6*Assumption!$G$30/365 -> 2430.4981
A21: Accrued Liabilities, Current | B21: 2145.1 | C21: 2194.7 | D21: 2359.7 | F21: 2359.7 | G21: 2359.7 | H21: 2359.7 | I21: 2359.7 | J21: 2359.7
A22: Accrued payroll and benefits | B22: 828.3 | C22: 786.6 | D22: 1093.9 | F22: 1093.9 | G22: 1093.9 | H22: 1093.9 | I22: 1093.9 | J22: 1093.9
A23: Operating Lease, Liability, Current | B23: 1275.3 | C23: 1463.1 | D23: 1564.5 | F23: 1564.5 | G23: 1564.5 | H23: 1564.5 | I23: 1564.5 | J23: 1564.5
A24: Deferred Revenue, Current | B24: 1700.2 | C24: 1781.2 | D24: 1840.6 | F24: 1840.6 | G24: 1840.6 | H24: 1840.6 | I24: 1840.6 | J24: 1840.6
A25: Short-term Debt | B25: 33.5 | C25: 0 | D25: 0 | F25: 0 | G25: 0 | H25: 0 | I25: 0 | J25: 0
A26: Long-term Debt, Current Maturities | B26: 1818.6 | C26: 1248.9 | D26: 1498.9 | F26: 1498.9 | G26: 1498.9 | H26: 1498.9 | I26: 1498.9 | J26: 1498.9
A27: Liabilities, Current | B27: =SUM(B20:B26) -> 9345.3 | C27: 9070 | D27: 10210.4 | F27: =SUM(F20:F26) -> 10186.181 | G27: =SUM(G20:G26) -> 10314.182 | H27: =SUM(H20:H26) -> 10451.142 | I27: =SUM(I20:I26) -> 10629.094 | J27: =SUM(J20:J26) -> 10788.098
A28: Long-term Debt, Excluding Current Maturities | B28: 13547.6 | C28: 14319.5 | D28: 14575.9 | F28: 14575.9 | G28: 14575.9 | H28: 14575.9 | I28: 14575.9 | J28: 14575.9
A29: Operating Lease, Liability, Noncurrent | B29: 7924.8 | C29: 8771.6 | D29: 8972.2 | F29: 8972.2 | G29: 8972.2 | H29: 8972.2 | I29: 8972.2 | J29: 8972.2
A30: Deferred Revenue, Noncurrent | B30: 6101.8 | C30: 5963.6 | D30: 5772.6 | F30: 5772.6 | G30: 5772.6 | H30: 5772.6 | I30: 5772.6 | J30: 5772.6
A31: Deferred Tax and Other Liabilities, Noncurrent | B31: 513.8 | C31: 656.2 | D31: 577.8 | F31: 577.8 | G31: 577.8 | H31: 577.8 | I31: 577.8 | J31: 577.8
A32: Liabilities | B32: =SUM(B27:B31) -> 37433.3 | C32: 38780.9 | D32: 40108.9 | F32: =SUM(F27:F31) -> 40084.681 | G32: =SUM(G27:G31) -> 40212.682 | H32: =SUM(H27:H31) -> 40349.642 | I32: =SUM(I27:I31) -> 40527.594 | J32: =SUM(J27:J31) -> 40686.598
A33: Shareholders' equity/(deficit)
A34: Common stock ($0.001 par value) - authorized 2,400.0 shares; issued and outstanding 1,136.9 and 1,133.5 shares, respectively | B34: 1.1 | C34: 1.1 | D34: 1.1 | F34: 1.1 | G34: 1.1 | H34: 1.1 | I34: 1.1 | J34: 1.1
A35: Additional Paid in Capital, Common Stock | B35: 38.1 | C35: 322.6 | D35: 634.1 | F35: 634.1 | G35: 634.1 | H35: 634.1 | I35: 634.1 | J35: 634.1
A36: Retained Earnings (Accumulated Deficit) | B36: -7255.8 | C36: -7343.8 | D36: -8272.5 | F36: =D36+IS!G20-IS!G5*Assumption!$G$33 -> -5492.0261 | G36: =F36+IS!H20-IS!H5*Assumption!$G$33 -> -2565.3895 | H36: =F36+IS!I20-IS!I5*Assumption!$G$33 -> -2409.6035 | I36: =H36+IS!J20-IS!J5*Assumption!$G$33 -> 876.6277 | J36: =I36+IS!K20-IS!K5*Assumption!$G$33 -> 4344.4245
A37: Accumulated Other Comprehensive Income (Loss), Net of Tax | B37: -778.2 | C37: -428.8 | D37: -459.3 | F37: -459.3 | G37: -459.3 | H37: -459.3 | I37: -459.3 | J37: -459.3
A38: Stockholders' Equity/(Deficit) Attributable to Parent | B38: -7994.8 | C38: -7448.9 | D38: -8096.6 | F38: =SUM(F36:F37) -> -5951.3261 | G38: =SUM(G36:G37) -> -3024.6895 | H38: =SUM(H36:H37) -> -2868.9035 | I38: =SUM(I36:I37) -> 417.3277 | J38: =SUM(J36:J37) -> 3885.1245
A39: Stockholders' Equity Attributable to Noncontrolling Interest | B39: 7 | C39: 7.3 | D39: 7.4 | F39: 7.4 | G39: 7.4 | H39: 7.4 | I39: 7.4 | J39: 7.4
A40: Stockholders' Equity/(Deficit), Including Portion Attributable to Noncontrolling Interest | B40: 7987.8 | C40: -7441.6 | D40: -8089.2 | F40: =SUM(F38:F39) -> -5943.9261 | G40: =SUM(G38:G39) -> -3017.2895 | H40: =SUM(H38:H39) -> -2861.5035 | I40: =SUM(I38:I39) -> 424.7277 | J40: =SUM(J38:J39) -> 3892.5245
...

Sheet Cash Flow 
B2: Consolidated Statements of Cash Flows - USD ($) | D2: 12 Months Ended | G2: 12 Months Ended
B3: $ in Millions | C3: Oct. 01, 2023 | D3: Sep. 29, 2024 | E3: Sep. 28, 2025 | G3: 2026 | H3: 2027 | I3: 2028 | J3: 2029 | K3: 2030
B4: OPERATING ACTIVITIES:
B5: Net earnings including noncontrolling interests | C5: $ 4,124.7 | D5: $ 3,762.3 | E5: $ 1,856.7 | G5: =IS!G20 -> 5167.7124 | H5: =IS!H20 -> 5480.9818 | I5: =IS!I20 -> 5815.572 | J5: =IS!J20 -> 6251.6982 | K5: =IS!K20 -> 6640.8465
B6: Adjustments to reconcile net earnings to net cash provided by operating activities:
B7: Depreciation and amortization | C7: 1450.3 | D7: 1592.4 | E7: 1771.5 | G7: =IS!G10 -> 1710.8542 | H7: =IS!H10 -> 1830.614 | I7: =IS!I10 -> 1958.757 | J7: =IS!J10 -> 2125.2514 | K7: =IS!K10 -> 2274.019
B8: Deferred income taxes, net | C8: -59.4 | D8: -13.8 | E8: -90.6 | G8: -90.6 | H8: -90.6 | I8: -90.6 | J8: -90.6 | K8: -90.6
B9: Income earned from equity method investees | C9: -301.8 | D9: -306.4 | E9: -274.2 | G9: -274.2 | H9: -274.2 | I9: -274.2 | J9: -274.2 | K9: -274.2
B10: Distributions received from equity method investees | C10: 222.8 | D10: 333.3 | E10: 294.4 | G10: 294.4 | H10: 294.4 | I10: 294.4 | J10: 294.4 | K10: 294.4
B11: Gain (Loss) on Disposition of Assets | C11: -91.3 | D11: 0 | E11: 0 | G11: 0 | H11: 0 | I11: 0 | J11: 0 | K11: 0
B12: Stock-based compensation | C12: 302.7 | D12: 308.3 | E12: 318.3 | G12: 318.3 | H12: 318.3 | I12: 318.3 | J12: 318.3 | K12: 318.3
B13: Non-cash Lease Cost | C13: 1365.9 | D13: 1314.9 | E13: 1513.8 | G13: 1513.8 | H13: 1513.8 | I13: 1513.8 | J13: 1513.8 | K13: 1513.8
B14: Loss on retirement and impairment of assets | C14: 101.4 | D14: 121.5 | E14: 834.7 | G14: 0 | H14: 0 | I14: 0 | J14: 0 | K14: 0
B15: Other | C15: 26.8 | D15: 31.9 | E15: 17.3 | G15: 17.3 | H15: 17.3 | I15: 17.3 | J15: 17.3 | K15: 17.3
B16: Cash provided/(used) by changes in operating assets and liabilities:
B17: Accounts receivable | C17: -4.1 | D17: 18.4 | E17: -89.7 | G17: =-((Assumption!$G$28/365)*(IS!G5-IS!E5)) -> -85.575058 | H17: =-((Assumption!$G$28/365)*(IS!H5-IS!G5)) -> -91.565312 | I17: =-((Assumption!$G$28/365)*(IS!I5-IS!H5)) -> -97.974883 | J17: =-((Assumption!$G$28/365)*(IS!J5-IS!I5)) -> -127.29737 | K17: =-((Assumption!$G$28/365)*(IS!K5-IS!J5)) -> -113.74394
B18: Inventories | C18: 366.4 | D18: 42.8 | E18: -408.4 | G18: =-((Assumption!$G$29/365)*(IS!G6-IS!E6)) -> -81.012587 | H18: =-((Assumption!$G$29/365)*(IS!H6-IS!G6)) -> -144.29167 | I18: =-((Assumption!$G$29/365)*(IS!I6-IS!H6)) -> -154.39209 | J18: =-((Assumption!$G$29/365)*(IS!J6-IS!I6)) -> -200.59943 | K18: =-((Assumption!$G$29/365)*(IS!K6-IS!J6)) -> -179.24149
B19: Income Taxes Payable | C19: 52.5 | D19: -61.9 | E19: 103.8 | G19: 103.8 | H19: 103.8 | I19: 103.8 | J19: 103.8 | K19: 103.8
B20: Accounts payable | C20: 100.1 | D20: 28 | E20: 261 | G20: =(Assumption!$G$30/365)*(IS!G6-IS!E6) -> 71.866005 | H20: =(Assumption!$G$30/365)*(IS!H5-IS!G5) -> 419.67434 | I20: =(Assumption!$G$30/365)*(IS!I6-IS!H6) -> 136.96072 | J20: =(Assumption!$G$30/365)*(IS!J6-IS!I6) -> 177.95111 | K20: =(Assumption!$G$30/365)*(IS!K6-IS!J6) -> 159.00455
B21: Deferred revenue | C21: -110.8 | D21: -72.2 | E21: -120.7 | G21: -120.7 | H21: -120.7 | I21: -120.7 | J21: -120.7 | K21: -120.7
B22: Operating lease liability | C22: -1443.8 | D22: -1294.9 | E22: -1576.7 | G22: -1576.7 | H22: -1576.7 | I22: -1576.7 | J22: -1576.7 | K22: -1576.7
B23: Other operating assets and liabilities | C23: -93.7 | D23: 291 | E23: 336.3 | G23: 336.3 | H23: 336.3 | I23: 336.3 | J23: 336.3 | K23: 336.3
B24: Cash Provided by (Used in) Operating Activity, Including Discontinued Operation | C24: 6008.7 | D24: 6095.6 | E24: 4747.5 | G24: =SUM(G4:G23) -> 7305.545 | H24: =SUM(H4:H23) -> 8017.1132 | I24: =SUM(I4:I23) -> 8180.6227 | J24: =SUM(J4:J23) -> 8748.7039 | K24: =SUM(K4:K23) -> 9302.5846
B25: INVESTING ACTIVITIES:
B26: Purchases of investments | C26: -610.5 | D26: -627.5 | E26: -333.6 | G26: -333.6 | H26: -333.6 | I26: -333.6 | J26: -333.6 | K26: -333.6
B27: Proceeds from Sales of Assets, Investing Activities | C27: 2.5 | D27: 10.3 | E27: 1.1 | G27: 1.1 | H27: 1.1 | I27: 1.1 | J27: 1.1 | K27: 1.1
B28: Maturities and calls of investments | C28: 616.9 | D28: 768.2 | E28: 391.8 | G28: 391.8 | H28: 391.8 | I28: 391.8 | J28: 391.8 | K28: 391.8
B29: Additions to property, plant and equipment | C29: -2333.6 | D29: -2777.5 | E29: -2305.5 | G29: =-IS!G5*Assumption!$G$25 -> -2387.2385 | H29: =-IS!H5*Assumption!$G$25 -> -2554.3452 | I29: =-IS!I5*Assumption!$G$25 -> -2733.1493 | J29: =-IS!J5*Assumption!$G$25 -> -2965.467 | K29: =-IS!K5*Assumption!$G$25 -> -3173.0497
B30: Payments to Acquire Businesses, Net of Cash Acquired | C30: 0 | D30: 0 | E30: -177.1 | G30: 0 | H30: 0 | I30: 0 | J30: 0 | K30: 0
B31: Proceeds from Sale of Productive Assets | C31: 110 | D31: 0 | E31: 0 | G31: 0 | H31: 0 | I31: 0 | J31: 0 | K31: 0
B32: Other | C32: -56.1 | D32: -72.7 | E32: -62.1 | G32: -62.1 | H32: -62.1 | I32: -62.1 | J32: -62.1 | K32: -62.1
B33: Net cash used by investing activities | C33: -2270.8 | D33: -2699.2 | E33: -2485.4 | G33: =SUM(G26:G32) -> -2390.0385 | H33: =SUM(H26:H32) -> -2557.1452 | I33: =SUM(I26:I32) -> -2735.9493 | J33: =SUM(J26:J32) -> -2968.267 | K33: =SUM(K26:K32) -> -3175.8497
B34: FINANCING ACTIVITIES:
B35: Proceeds from (Repayments of) Commercial Paper | C35: -175 | D35: 0 | E35: 0 | G35: 0 | H35: 0 | I35: 0 | J35: 0 | K35: 0
B36: Proceeds from issuance of short-term debt | C36: 114.6 | D36: 123.8 | E36: 2.4 | G36: 0 | H36: 0 | I36: 0 | J36: 0 | K36: 0
B37: Repayments of Short-term Debt | C37: -78.8 | D37: -157.5 | E37: -7.8 | G37: 0 | H37: 0 | I37: 0 | J37: 0 | K37: 0
B38: Proceeds from issuance of long-term debt | C38: 1497.8 | D38: 1995.3 | E38: 1748.5 | G38: 1748.5 | H38: 1748.5 | I38: 1748.5 | J38: 1748.5 | K38: 1748.5
B39: Repayments of long-term debt | C39: -1000 | D39: -1825.1 | E39: -1250 | G39: -1250 | H39: -1250 | I39: -1250 | J39: -1250 | K39: -1250
B40: Proceeds from issuance of common stock | C40: 167.4 | D40: 108 | E40: 77 | G40: 77 | H40: 77 | I40: 77 | J40: 77 | K40: 77
B41: Cash dividends paid | C41: -2431.8 | D41: -2585 | E41: -2771.4 | G41: =E41*(1+Assumption!$G$33) -> -2937.684 | H41: =G41*(1+Assumption!$G$33) -> -3113.945 | I41: =H41*(1+Assumption!$G$33) -> -3300.7817 | J41: =I41*(1+Assumption!$G$33) -> -3498.8286 | K41: =J41*(1+Assumption!$G$33) -> -3708.7584
...

Sheet Assumption
A1: Assumptions | B1: Historical Avg | C1: Bear | D1: Base | E1: Bull | G1: ACTIVE
A2: Select Scenario | C2: Bull | G2: =IF($C$2="Bear",C2,IF($C$2="Base",D2,E2)) -> 0
A3: Revenue
A4: Revenue Growth FY2026 | B4: 0.022 | C4: 0.02 | D4: 0.045 | E4: 0.07 | G4: =IF($C$2="Bear",C4,IF($C$2="Base",D4,E4)) -> 0.07
A5: Revenue Growth FY2027 | B5: 0.022 | C5: 0.03 | D5: 0.06 | E5: 0.09 | G5: =IF($C$2="Bear",C5,IF($C$2="Base",D5,E5)) -> 0.09
A6: Revenue Growth FY2028 | B6: 0.022 | C6: 0.035 | D6: 0.07 | E6: 0.1 | G6: =IF($C$2="Bear",C6,IF($C$2="Base",D6,E6)) -> 0.1
A7: Revenue Growth FY2029 | B7: 0.022 | C7: 0.035 | D7: 0.06 | E7: 0.085 | G7: =IF($C$2="Bear",C7,IF($C$2="Base",D7,E7)) -> 0.085
A8: Revenue Growth FY2030 | B8: 0.022 | C8: 0.03 | D8: 0.05 | E8: 0.07 | G8: =IF($C$2="Bear",C8,IF($C$2="Base",D8,E8)) -> 0.07
A10: Margins
A11: Gross Margin % | B11: 0.685 | C11: 0.675 | D11: 0.685 | E11: 0.695 | G11: =IF($C$2="Bear",C11,IF($C$2="Base",D11,E11)) -> 0.695
A13: Operating Expenses
A14: Store Opex % | B14: 0.445 | C14: 0.459 | D14: 0.44 | E14: 0.42 | G14: =IF($C$2="Bear",C14,IF($C$2="Base",D14,E14)) -> 0.42
A15: G&A % | B15: 0.07 | C15: 0.071 | D15: 0.07 | E15: 0.069 | G15: =IF($C$2="Bear",C15,IF($C$2="Base",D15,E15)) -> 0.069
A16: D&A % | B16: 0.0417 | C16: 0.046 | D16: 0.045 | E16: 0.043 | G16: =IF($C$2="Bear",C16,IF($C$2="Base",D16,E16)) -> 0.043
A17: Other Operating % | B17: 0.016 | C17: 0.016 | D17: 0.016 | E17: 0.015 | G17: =IF($C$2="Bear",C17,IF($C$2="Base",D17,E17)) -> 0.015
A18: Restructuring | B18: 0 | C18: 0 | D18: 0 | E18: 0
A20: Tax & Interest
A21: Tax Rate % | B21: 0.245 | C21: 0.245 | D21: 0.245 | E21: 0.24 | G21: =IF($C$2="Bear",C21,IF($C$2="Base",D21,E21)) -> 0.24
A22: Interest Expense ($M) | B22: 550 | C22: 550 | D22: 540 | E22: 530 | G22: =IF($C$2="Bear",C22,IF($C$2="Base",D22,E22)) -> 530
A24: Capex
A25: Capex % of Revenue | B25: 0.068 | C25: 0.065 | D25: 0.065 | E25: 0.06 | G25: =IF($C$2="Bear",C25,IF($C$2="Base",D25,E25)) -> 0.06
A27: Working Capital
A28: DSO (Receivable Days) | B28: 12.6 | C28: 12.5 | D28: 12.5 | E28: 12 | G28: =IF($C$2="Bear",C28,IF($C$2="Base",D28,E28)) -> 12
A29: DIO (Inventory Days) | B29: 61.4 | C29: 65 | D29: 65 | E29: 62 | G29: =IF($C$2="Bear",C29,IF($C$2="Base",D29,E29)) -> 62
A30: DPO (Payable Days) | B30: 53.2 | C30: 58 | D30: 58 | E30: 55 | G30: =IF($C$2="Bear",C30,IF($C$2="Base",D30,E30)) -> 55
A32: Dividends
A33: Dividend Growth % | B33: 0.05 | C33: 0.03 | D33: 0.05 | E33: 0.06 | G33: =IF($C$2="Bear",C33,IF($C$2="Base",D33,E33)) -> 0.06

Sheet DCF
B2: Starbucks Corp (SBUX) - DCF Valuation
B3: All figures in $ millions unless noted
B5: WACC — Inputs & Calculation
B7: Cost of Equity (CAPM)
B8: Risk-free rate (10Y UST) | C8: 0.043
B9: Beta | C9: 0.9
B10: Equity risk premium | C10: 0.055
B11: Cost of Equity = Rf + Beta × ERP | C11: =C8+C9*C10 -> 0.0925
B13: Cost of Debt
B14: Interest expense (from IS, FY26 avg) | C14: =-IS!G17 -> 550
B15: Total debt (from BS, FY26) | C15: ='Balance Sheet'!F26+'Balance Sheet'!F28 -> 16074.8
B16: Pre-tax Cost of Debt | C16: =C14/C15 -> 0.034215045
B17: Tax rate (from Assumption) | C17: =Assumption!$G$21 -> 0.24
B18: After-tax Cost of Debt | C18: =C16*(1-C17) -> 0.026003434
B20: Capital Structure
B21: Share price (input, $) | C21: 105
B22: Shares outstanding (mm) | C22: =IS!G26 -> 1136
B23: Market cap ($M) | C23: =C21*C22 -> 119280
B24: Total debt ($M) | C24: =C15 -> 16074.8
B25: Total capital ($M) | C25: =C23+C24 -> 135354.8
B26: Weight of Equity (E/V) | C26: =C23/C25 -> 0.88123953
B27: Weight of Debt (D/V) | C27: =C24/C25 -> 0.11876047
B29: WACC = (E/V × Re) + (D/V × Rd × (1-t)) | C29: =C26*C11+C27*C18 -> 0.084602836
B32: Free Cash Flow to Firm (FCFF) — CFO less Capex approach
D34: 2026 | E34: 2027 | F34: 2028 | G34: 2029 | H34: 2030
B35: Cash from Operations (CFO) | D35: ='Cash Flow '!G24 -> 7305.545 | E35: ='Cash Flow '!H24 -> 8017.1132 | F35: ='Cash Flow '!I24 -> 8180.6227 | G35: ='Cash Flow '!J24 -> 8748.7039 | H35: ='Cash Flow '!K24 -> 9302.5846
B36: Less: Capex (positive value) | D36: =-'Cash Flow '!G29 -> 2387.2385 | E36: =-'Cash Flow '!H29 -> 2554.3452 | F36: =-'Cash Flow '!I29 -> 2733.1493 | G36: =-'Cash Flow '!J29 -> 2965.467 | H36: =-'Cash Flow '!K29 -> 3173.0497
B37: FCFF = CFO − Capex | D37: =D35-D36 -> 4918.3065 | E37: =E35-E36 -> 5462.768 | F37: =F35-F36 -> 5447.4734 | G37: =G35-G36 -> 5783.2368 | H37: =H35-H36 -> 6129.5349
B40: Terminal Value
B42: Terminal growth rate (g) | C42: 0.025
B43: WACC (from above) | C43: =C29 -> 0.084602836
B44: Terminal Value at end of FY30 = FCFF_FY30 × (1+g) / (WACC − g) | C44: =H37*(1+C42)/(C43-C42) -> 105410.64
B47: DCF Valuation
B49: Year (from valuation date) | D49: 1 | E49: 2 | F49: 3 | G49: 4 | H49: 5
B50: Discount factor = 1 / (1+WACC)^n | D50: =1/(1+$C$29)^D49 -> 0.92199648 | E50: =1/(1+$C$29)^E49 -> 0.85007751 | F50: =1/(1+$C$29)^F49 -> 0.78376848 | G50: =1/(1+$C$29)^G49 -> 0.72263178 | H50: =1/(1+$C$29)^H49 -> 0.66626396
B51: PV of FCFF | D51: =D37*D50 -> 4534.6613 | E51: =E37*E50 -> 4643.7762 | F51: =F37*F50 -> 4269.5579 | G51: =G37*G50 -> 4179.1507 | H51: =H37*H50 -> 4083.8882
B53: Sum of PV of FCFF (FY26–FY30) | C53: =SUM(D51:H51) -> 21711.034
B54: PV of Terminal Value = TV × discount factor FY30 | C54: =C44*H50 -> 70231.312
B55: Enterprise Value | C55: =C53+C54 -> 91942.346
B57: Less: Total debt (FY26) | C57: =C15 -> 16074.8
...
